<mujoco model="wxai_biarm">
  <compiler angle="radian"/>

  <size nkey="2"/>

  <visual>
    <headlight ambient="0.3 0.3 0.3" diffuse="0.8 0.8 0.8" specular="0 0 0"/>
    <scale forcewidth="0.03" contactwidth="0.05" contactheight="0.02"/>
  </visual>

  <default>
    <mesh maxhullvert="64"/>
    <default class="left/main">
      <default class="left/visual">
        <geom type="mesh" contype="0" conaffinity="0" group="1" density="0" material="trossen_material"/>
      </default>
      <default class="left/collision">
        <geom type="mesh" group="3" friction="1 0.005 0.0005" solref="0.01"/>
        <default class="left/gripper_collision">
          <geom condim="6"/>
        </default>
      </default>
    </default>
    <default class="right/main">
      <default class="right/visual">
        <geom type="mesh" contype="0" conaffinity="0" group="1" density="0" material="trossen_material"/>
      </default>
      <default class="right/collision">
        <geom type="mesh" group="3" friction="1 0.005 0.0005" solref="0.01"/>
        <default class="right/gripper_collision">
          <geom condim="6"/>
        </default>
      </default>
    </default>
  </default>

  <asset>
    <texture type="2d" colorspace="linear" name="left/trossen_BaseColor"
      file="assets/materials/1k_textures/trossen_BaseColor.png"/>
    <texture type="2d" colorspace="linear" name="right/trossen_BaseColor"
      file="assets/materials/1k_textures/trossen_BaseColor.png"/>
    <material name="left/trossen_material" texture="left/trossen_BaseColor"/>
    <material name="right/trossen_material" texture="right/trossen_BaseColor"/>
    <mesh name="left/base_link" content_type="model/obj" file="assets/meshes/wxai/base_link.obj"/>
    <mesh name="left/link_1" content_type="model/obj" file="assets/meshes/wxai/link_1.obj"/>
    <mesh name="left/link_2" content_type="model/obj" file="assets/meshes/wxai/link_2.obj"/>
    <mesh name="left/link_3" content_type="model/obj" file="assets/meshes/wxai/link_3.obj"/>
    <mesh name="left/link_4" content_type="model/obj" file="assets/meshes/wxai/link_4.obj"/>
    <mesh name="left/link_5" content_type="model/obj" file="assets/meshes/wxai/link_5.obj"/>
    <mesh name="left/link_6" content_type="model/obj" file="assets/meshes/wxai/link_6.obj"/>
    <mesh name="left/carriage_right" content_type="model/obj" file="assets/meshes/wxai/carriage_right.obj"/>
    <mesh name="left/carriage_left" content_type="model/obj" file="assets/meshes/wxai/carriage_left.obj"/>
    <mesh name="left/camera_mount_d405" content_type="model/obj" file="assets/meshes/d405/camera_mount_d405.obj"/>
    <mesh name="left/d405" content_type="model/stl" file="assets/meshes/d405/d405.stl" scale="0.001 0.001 0.001"/>
    <mesh name="left/gripper_left" content_type="model/obj" file="assets/meshes/wxai/gripper_left.obj"/>
    <mesh name="left/gripper_right" content_type="model/obj" file="assets/meshes/wxai/gripper_right.obj"/>
    <mesh name="left/base_link_collision" content_type="model/obj" file="assets/meshes/wxai/base_link_collision.obj"/>
    <mesh name="left/base_link_collision.001" content_type="model/obj"
      file="assets/meshes/wxai/base_link_collision.001.obj"/>
    <mesh name="left/base_link_collision.002" content_type="model/obj"
      file="assets/meshes/wxai/base_link_collision.002.obj"/>
    <mesh name="left/base_link_collision.003" content_type="model/obj"
      file="assets/meshes/wxai/base_link_collision.003.obj"/>
    <mesh name="left/camera_mount_d405_collision" content_type="model/obj"
      file="assets/meshes/d405/camera_mount_d405_collision.obj"/>
    <mesh name="left/camera_mount_d405_collision.001" content_type="model/obj"
      file="assets/meshes/d405/camera_mount_d405_collision.001.obj"/>
    <mesh name="left/carriage_left_collision" content_type="model/obj"
      file="assets/meshes/wxai/carriage_left_collision.obj"/>
    <mesh name="left/carriage_right_collision" content_type="model/obj"
      file="assets/meshes/wxai/carriage_right_collision.obj"/>
    <mesh name="left/gripper_left_collision" content_type="model/obj"
      file="assets/meshes/wxai/gripper_left_collision.obj"/>
    <mesh name="left/gripper_right_collision" content_type="model/obj"
      file="assets/meshes/wxai/gripper_right_collision.obj"/>
    <mesh name="left/link_1_collision" content_type="model/obj" file="assets/meshes/wxai/link_1_collision.obj"/>
    <mesh name="left/link_1_collision.001" content_type="model/obj" file="assets/meshes/wxai/link_1_collision.001.obj"/>
    <mesh name="left/link_1_collision.002" content_type="model/obj" file="assets/meshes/wxai/link_1_collision.002.obj"/>
    <mesh name="left/link_1_collision.003" content_type="model/obj" file="assets/meshes/wxai/link_1_collision.003.obj"/>
    <mesh name="left/link_2_collision" content_type="model/obj" file="assets/meshes/wxai/link_2_collision.obj"/>
    <mesh name="left/link_2_collision.001" content_type="model/obj" file="assets/meshes/wxai/link_2_collision.001.obj"/>
    <mesh name="left/link_2_collision.002" content_type="model/obj" file="assets/meshes/wxai/link_2_collision.002.obj"/>
    <mesh name="left/link_2_collision.003" content_type="model/obj" file="assets/meshes/wxai/link_2_collision.003.obj"/>
    <mesh name="left/link_3_collision" content_type="model/obj" file="assets/meshes/wxai/link_3_collision.obj"/>
    <mesh name="left/link_3_collision.001" content_type="model/obj" file="assets/meshes/wxai/link_3_collision.001.obj"/>
    <mesh name="left/link_3_collision.002" content_type="model/obj" file="assets/meshes/wxai/link_3_collision.002.obj"/>
    <mesh name="left/link_3_collision.003" content_type="model/obj" file="assets/meshes/wxai/link_3_collision.003.obj"/>
    <mesh name="left/link_3_collision.004" content_type="model/obj" file="assets/meshes/wxai/link_3_collision.004.obj"/>
    <mesh name="left/link_4_collision" content_type="model/obj" file="assets/meshes/wxai/link_4_collision.obj"/>
    <mesh name="left/link_4_collision.001" content_type="model/obj" file="assets/meshes/wxai/link_4_collision.001.obj"/>
    <mesh name="left/link_4_collision.002" content_type="model/obj" file="assets/meshes/wxai/link_4_collision.002.obj"/>
    <mesh name="left/link_5_collision" content_type="model/obj" file="assets/meshes/wxai/link_5_collision.obj"/>
    <mesh name="left/link_6_collision" content_type="model/obj" file="assets/meshes/wxai/link_6_collision.obj"/>
    <mesh name="right/base_link" content_type="model/obj" file="assets/meshes/wxai/base_link.obj"/>
    <mesh name="right/link_1" content_type="model/obj" file="assets/meshes/wxai/link_1.obj"/>
    <mesh name="right/link_2" content_type="model/obj" file="assets/meshes/wxai/link_2.obj"/>
    <mesh name="right/link_3" content_type="model/obj" file="assets/meshes/wxai/link_3.obj"/>
    <mesh name="right/link_4" content_type="model/obj" file="assets/meshes/wxai/link_4.obj"/>
    <mesh name="right/link_5" content_type="model/obj" file="assets/meshes/wxai/link_5.obj"/>
    <mesh name="right/link_6" content_type="model/obj" file="assets/meshes/wxai/link_6.obj"/>
    <mesh name="right/carriage_right" content_type="model/obj" file="assets/meshes/wxai/carriage_right.obj"/>
    <mesh name="right/carriage_left" content_type="model/obj" file="assets/meshes/wxai/carriage_left.obj"/>
    <mesh name="right/camera_mount_d405" content_type="model/obj" file="assets/meshes/d405/camera_mount_d405.obj"/>
    <mesh name="right/d405" content_type="model/stl" file="assets/meshes/d405/d405.stl" scale="0.001 0.001 0.001"/>
    <mesh name="right/gripper_left" content_type="model/obj" file="assets/meshes/wxai/gripper_left.obj"/>
    <mesh name="right/gripper_right" content_type="model/obj" file="assets/meshes/wxai/gripper_right.obj"/>
    <mesh name="right/base_link_collision" content_type="model/obj" file="assets/meshes/wxai/base_link_collision.obj"/>
    <mesh name="right/base_link_collision.001" content_type="model/obj"
      file="assets/meshes/wxai/base_link_collision.001.obj"/>
    <mesh name="right/base_link_collision.002" content_type="model/obj"
      file="assets/meshes/wxai/base_link_collision.002.obj"/>
    <mesh name="right/base_link_collision.003" content_type="model/obj"
      file="assets/meshes/wxai/base_link_collision.003.obj"/>
    <mesh name="right/camera_mount_d405_collision" content_type="model/obj"
      file="assets/meshes/d405/camera_mount_d405_collision.obj"/>
    <mesh name="right/camera_mount_d405_collision.001" content_type="model/obj"
      file="assets/meshes/d405/camera_mount_d405_collision.001.obj"/>
    <mesh name="right/carriage_left_collision" content_type="model/obj"
      file="assets/meshes/wxai/carriage_left_collision.obj"/>
    <mesh name="right/carriage_right_collision" content_type="model/obj"
      file="assets/meshes/wxai/carriage_right_collision.obj"/>
    <mesh name="right/gripper_left_collision" content_type="model/obj"
      file="assets/meshes/wxai/gripper_left_collision.obj"/>
    <mesh name="right/gripper_right_collision" content_type="model/obj"
      file="assets/meshes/wxai/gripper_right_collision.obj"/>
    <mesh name="right/link_1_collision" content_type="model/obj" file="assets/meshes/wxai/link_1_collision.obj"/>
    <mesh name="right/link_1_collision.001" content_type="model/obj"
      file="assets/meshes/wxai/link_1_collision.001.obj"/>
    <mesh name="right/link_1_collision.002" content_type="model/obj"
      file="assets/meshes/wxai/link_1_collision.002.obj"/>
    <mesh name="right/link_1_collision.003" content_type="model/obj"
      file="assets/meshes/wxai/link_1_collision.003.obj"/>
    <mesh name="right/link_2_collision" content_type="model/obj" file="assets/meshes/wxai/link_2_collision.obj"/>
    <mesh name="right/link_2_collision.001" content_type="model/obj"
      file="assets/meshes/wxai/link_2_collision.001.obj"/>
    <mesh name="right/link_2_collision.002" content_type="model/obj"
      file="assets/meshes/wxai/link_2_collision.002.obj"/>
    <mesh name="right/link_2_collision.003" content_type="model/obj"
      file="assets/meshes/wxai/link_2_collision.003.obj"/>
    <mesh name="right/link_3_collision" content_type="model/obj" file="assets/meshes/wxai/link_3_collision.obj"/>
    <mesh name="right/link_3_collision.001" content_type="model/obj"
      file="assets/meshes/wxai/link_3_collision.001.obj"/>
    <mesh name="right/link_3_collision.002" content_type="model/obj"
      file="assets/meshes/wxai/link_3_collision.002.obj"/>
    <mesh name="right/link_3_collision.003" content_type="model/obj"
      file="assets/meshes/wxai/link_3_collision.003.obj"/>
    <mesh name="right/link_3_collision.004" content_type="model/obj"
      file="assets/meshes/wxai/link_3_collision.004.obj"/>
    <mesh name="right/link_4_collision" content_type="model/obj" file="assets/meshes/wxai/link_4_collision.obj"/>
    <mesh name="right/link_4_collision.001" content_type="model/obj"
      file="assets/meshes/wxai/link_4_collision.001.obj"/>
    <mesh name="right/link_4_collision.002" content_type="model/obj"
      file="assets/meshes/wxai/link_4_collision.002.obj"/>
    <mesh name="right/link_5_collision" content_type="model/obj" file="assets/meshes/wxai/link_5_collision.obj"/>
    <mesh name="right/link_6_collision" content_type="model/obj" file="assets/meshes/wxai/link_6_collision.obj"/>
  </asset>

  <worldbody>
    <site name="left_attach" pos="-0.41 -0.019 0"/>
    <site name="right_attach" pos="0.41 -0.019 0" quat="0 0 0 1"/>
    <body name="left/base_link" pos="-0.41 -0.019 0">
      <inertial pos="-0.00014175 -5.228e-05 0.0317518" quat="0.708444 0.00673042 0.00910019 0.705677" mass="0.459699"
        diaginertia="0.000448963 0.000416701 0.000213926"/>
      <geom class="left/visual" material="left/trossen_material" mesh="left/base_link"/>
      <geom class="left/collision" mesh="left/base_link_collision"/>
      <geom class="left/collision" mesh="left/base_link_collision.001"/>
      <geom class="left/collision" mesh="left/base_link_collision.002"/>
      <geom class="left/collision" mesh="left/base_link_collision.003"/>
      <body name="left/link_1" pos="0 0 0.05725">
        <inertial pos="-0.00011075 0.00171176 0.0204459" quat="0.313955 0.305238 -0.643575 0.627752" mass="0.152704"
          diaginertia="0.000203432 0.000173907 8.3521e-05"/>
        <joint name="left/joint_0" pos="0 0 0" axis="0 0 1" range="-3.05433 3.05433" actuatorfrcrange="-27 27"
          armature="0.844846" damping="14.1737"/>
        <geom class="left/visual" material="left/trossen_material" mesh="left/link_1"/>
        <geom class="left/collision" mesh="left/link_1_collision"/>
        <geom class="left/collision" mesh="left/link_1_collision.001"/>
        <geom class="left/collision" mesh="left/link_1_collision.002"/>
        <geom class="left/collision" mesh="left/link_1_collision.003"/>
        <body name="left/link_2" pos="0.02 0 0.04625">
          <inertial pos="-0.131215 -0.00292583 0.00021345" quat="-0.00123582 0.706546 -0.00109575 0.707665"
            mass="1.15316" diaginertia="0.0179449 0.0173612 0.00102628"/>
          <joint name="left/joint_1" pos="0 0 0" axis="0 1 0" range="0 3.14159" actuatorfrcrange="-27 27"
            armature="0.094783" damping="8.0188"/>
          <geom class="left/visual" material="left/trossen_material" mesh="left/link_2"/>
          <geom class="left/collision" mesh="left/link_2_collision"/>
          <geom class="left/collision" mesh="left/link_2_collision.001"/>
          <geom class="left/collision" mesh="left/link_2_collision.002"/>
          <geom class="left/collision" mesh="left/link_2_collision.003"/>
          <body name="left/link_3" pos="-0.264 0 0">
            <inertial pos="0.180836 -0.0009409 0.0555494" quat="0.0103901 0.669684 -0.0033175 0.742566" mass="0.686666"
              diaginertia="0.00566898 0.00547578 0.00059316"/>
            <joint name="left/joint_2" pos="0 0 0" axis="0 -1 0" range="0 2.35619" actuatorfrcrange="-27 27"
              damping="0.725663" frictionloss="0.1"/>
            <geom class="left/visual" material="left/trossen_material" mesh="left/link_3"/>
            <geom class="left/collision" mesh="left/link_3_collision"/>
            <geom class="left/collision" mesh="left/link_3_collision.001"/>
            <geom class="left/collision" mesh="left/link_3_collision.002"/>
            <geom class="left/collision" mesh="left/link_3_collision.003"/>
            <geom class="left/collision" mesh="left/link_3_collision.004"/>
            <body name="left/link_4" pos="0.245 0 0.06">
              <inertial pos="0.0579784 0.00027145 0.0588445" quat="0.948688 0.0346237 0.307828 0.0635164"
                mass="0.457899" diaginertia="0.000670827 0.000661455 0.000288648"/>
              <joint name="left/joint_3" pos="0 0 0" axis="0 -1 0" range="-1.5708 1.5708" actuatorfrcrange="-7 7"
                armature="0.131812" damping="2.31571" frictionloss="0.004603"/>
              <geom class="left/visual" material="left/trossen_material" mesh="left/link_4"/>
              <geom class="left/collision" mesh="left/link_4_collision"/>
              <geom class="left/collision" mesh="left/link_4_collision.001"/>
              <geom class="left/collision" mesh="left/link_4_collision.002"/>
              <body name="left/link_5" pos="0.06775 0 0.0455">
                <inertial pos="0.00412447 -1.138e-05 -0.0428318" quat="0.496144 0.502128 0.503595 0.498098"
                  mass="0.366939" diaginertia="0.000320622 0.00026751 0.000189108"/>
                <joint name="left/joint_4" pos="0 0 0" axis="0 0 -1" range="-1.5708 1.5708" actuatorfrcrange="-7 7"
                  armature="0.138205" damping="2.36817"/>
                <geom class="left/visual" material="left/trossen_material" mesh="left/link_5"/>
                <geom class="left/collision" mesh="left/link_5_collision"/>
                <body name="left/link_6" pos="0.02895 0 -0.0455">
                  <inertial pos="0.0457277 -7.26e-06 1.402e-05" quat="0.500491 0.4997 -0.500266 0.499542"
                    mass="0.554693" diaginertia="0.001086 0.000824291 0.000487589"/>
                  <joint name="left/joint_5" pos="0 0 0" axis="1 0 0" range="-3.14159 3.14159" actuatorfrcrange="-7 7"
                    armature="0.039831" damping="0.684856"/>
                  <geom class="left/visual" material="left/trossen_material" mesh="left/link_6"/>
                  <geom class="left/collision" mesh="left/link_6_collision"/>
                  <site name="left/ee_gripper_link" pos="0.156062 0 0" size="0.01" group="5" rgba="1 0 0 1"/>
                  <body name="left/camera_mount_d405" pos="0.012 0 0">
                    <inertial pos="0.0302338 0.00679835 0.0500669" quat="0.501514 0.851949 0.0948108 -0.116954"
                      mass="0.0451801" diaginertia="3.52003e-05 2.55005e-05 1.80592e-05"/>
                    <geom class="left/visual" material="left/trossen_material" mesh="left/camera_mount_d405"/>
                    <geom class="left/collision" mesh="left/camera_mount_d405_collision"/>
                    <geom class="left/collision" mesh="left/camera_mount_d405_collision.001"/>
                    <body name="left/camera_link" pos="0.04665 0.009 0.054272" quat="0.984808 0 0.173648 0">
                      <inertial pos="0 0 0" mass="0.072" diaginertia="2.117e-05 1.3758e-05 1.3758e-05"/>
                      <geom class="left/visual" pos="0.0038 -0.009 0" quat="0.5 0.5 0.5 0.5"
                        material="left/trossen_material" mesh="left/d405"/>
                      <geom class="left/collision" size="0.0115 0.021 0.021" pos="-0.0078 -0.009 0" type="box"/>
                      <camera name="left/wrist_cam" pos="0 0 0" quat="0.5 0.5 -0.5 -0.5" resolution="1280 720"
                        sensorsize="0.003896 0.00214" focal="0.00193 0.00193"/>
                    </body>
                  </body>
                  <body name="left/carriage_right" pos="0.0865 -0.023 0">
                    <inertial pos="-0.00889602 0.00403514 0.00457901" quat="0.616415 0.778591 0.0236991 -0.115186"
                      mass="0.0503631" diaginertia="1.77614e-05 1.40157e-05 5.27289e-06"/>
                    <joint name="left/right_carriage_joint" pos="0 0 0" axis="0 -1 0" type="slide" range="-0.01 0.045"
                      actuatorfrcrange="-400 400" armature="2.57487" damping="2.37396" frictionloss="0.1"/>
                    <geom class="left/visual" material="left/trossen_material" mesh="left/carriage_right"/>
                    <geom class="left/collision" mesh="left/carriage_right_collision"/>
                    <body name="left/gripper_right">
                      <inertial pos="0.0189399 0.00901216 -0.00215461" quat="0.382396 0.419236 0.596564 0.567562"
                        mass="0.0309079" diaginertia="1.60975e-05 1.18601e-05 6.44247e-06"/>
                      <geom class="left/visual" material="left/trossen_material" mesh="left/gripper_right"/>
                      <geom class="left/gripper_collision" pos="0 -0.00154 0" quat="1 0 0 0"
                        mesh="left/gripper_right_collision"/>
                      <geom class="left/gripper_collision" size="0.005 0.016 0.028" pos="-0.004 0 0" type="box"/>
                      <geom name="left/gripper_right_pad" class="left/gripper_collision" size="0.008 0.002 0.005"
                        pos="0.0615 0.021 0" type="box" rgba="0 0.5 0 0.5"/>
                      <geom class="left/gripper_collision" size="0.001" pos="0.062 0.0223 -0.005" type="sphere"/>
                      <geom class="left/gripper_collision" size="0.001" pos="0.067 0.0223 0" type="sphere"/>
                      <geom class="left/gripper_collision" size="0.001" pos="0.062 0.0223 0.005" type="sphere"/>
                    </body>
                  </body>
                  <body name="left/carriage_left" pos="0.0865 0.023 0">
                    <inertial pos="-0.00889602 -0.00403515 -0.00457908" quat="0.616415 0.778591 0.0236991 -0.115186"
                      mass="0.0503631" diaginertia="1.77614e-05 1.40157e-05 5.27289e-06"/>
                    <joint name="left/left_carriage_joint" pos="0 0 0" axis="0 1 0" type="slide" range="-0.01 0.045"
                      actuatorfrcrange="-400 400" armature="0.0005" damping="10.7" frictionloss="0.018"/>
                    <geom class="left/visual" material="left/trossen_material" mesh="left/carriage_left"/>
                    <geom class="left/collision" mesh="left/carriage_left_collision"/>
                    <body name="left/gripper_left">
                      <inertial pos="0.0189399 -0.00901223 -0.00215453" quat="0.567562 0.596564 0.419236 0.382396"
                        mass="0.0309079" diaginertia="1.60975e-05 1.18601e-05 6.44247e-06"/>
                      <geom class="left/visual" material="left/trossen_material" mesh="left/gripper_left"/>
                      <geom class="left/gripper_collision" pos="0 0.00154 0" quat="1 0 0 0"
                        mesh="left/gripper_left_collision"/>
                      <geom class="left/gripper_collision" size="0.005 0.016 0.028" pos="-0.004 0 0" type="box"/>
                      <geom name="left/gripper_left_pad" class="left/gripper_collision" size="0.008 0.002 0.005"
                        pos="0.0615 -0.021 0" type="box" rgba="0 0.5 0 0.5"/>
                      <geom class="left/gripper_collision" size="0.001" pos="0.062 -0.0223 -0.005" type="sphere"/>
                      <geom class="left/gripper_collision" size="0.001" pos="0.067 -0.0223 0" type="sphere"/>
                      <geom class="left/gripper_collision" size="0.001" pos="0.062 -0.0223 0.005" type="sphere"/>
                    </body>
                  </body>
                </body>
              </body>
            </body>
          </body>
        </body>
      </body>
    </body>
    <body name="right/base_link" pos="0.41 -0.019 0" quat="0 0 0 1">
      <inertial pos="-0.00014175 -5.228e-05 0.0317518" quat="0.708444 0.00673042 0.00910019 0.705677" mass="0.459699"
        diaginertia="0.000448963 0.000416701 0.000213926"/>
      <geom class="right/visual" material="right/trossen_material" mesh="right/base_link"/>
      <geom class="right/collision" mesh="right/base_link_collision"/>
      <geom class="right/collision" mesh="right/base_link_collision.001"/>
      <geom class="right/collision" mesh="right/base_link_collision.002"/>
      <geom class="right/collision" mesh="right/base_link_collision.003"/>
      <body name="right/link_1" pos="0 0 0.05725">
        <inertial pos="-0.00011075 0.00171176 0.0204459" quat="0.313955 0.305238 -0.643575 0.627752" mass="0.152704"
          diaginertia="0.000203432 0.000173907 8.3521e-05"/>
        <joint name="right/joint_0" pos="0 0 0" axis="0 0 1" range="-3.05433 3.05433" actuatorfrcrange="-27 27"
          armature="0.844846" damping="14.1737"/>
        <geom class="right/visual" material="right/trossen_material" mesh="right/link_1"/>
        <geom class="right/collision" mesh="right/link_1_collision"/>
        <geom class="right/collision" mesh="right/link_1_collision.001"/>
        <geom class="right/collision" mesh="right/link_1_collision.002"/>
        <geom class="right/collision" mesh="right/link_1_collision.003"/>
        <body name="right/link_2" pos="0.02 0 0.04625">
          <inertial pos="-0.131215 -0.00292583 0.00021345" quat="-0.00123582 0.706546 -0.00109575 0.707665"
            mass="1.15316" diaginertia="0.0179449 0.0173612 0.00102628"/>
          <joint name="right/joint_1" pos="0 0 0" axis="0 1 0" range="0 3.14159" actuatorfrcrange="-27 27"
            armature="0.094783" damping="8.0188"/>
          <geom class="right/visual" material="right/trossen_material" mesh="right/link_2"/>
          <geom class="right/collision" mesh="right/link_2_collision"/>
          <geom class="right/collision" mesh="right/link_2_collision.001"/>
          <geom class="right/collision" mesh="right/link_2_collision.002"/>
          <geom class="right/collision" mesh="right/link_2_collision.003"/>
          <body name="right/link_3" pos="-0.264 0 0">
            <inertial pos="0.180836 -0.0009409 0.0555494" quat="0.0103901 0.669684 -0.0033175 0.742566" mass="0.686666"
              diaginertia="0.00566898 0.00547578 0.00059316"/>
            <joint name="right/joint_2" pos="0 0 0" axis="0 -1 0" range="0 2.35619" actuatorfrcrange="-27 27"
              damping="0.725663" frictionloss="0.1"/>
            <geom class="right/visual" material="right/trossen_material" mesh="right/link_3"/>
            <geom class="right/collision" mesh="right/link_3_collision"/>
            <geom class="right/collision" mesh="right/link_3_collision.001"/>
            <geom class="right/collision" mesh="right/link_3_collision.002"/>
            <geom class="right/collision" mesh="right/link_3_collision.003"/>
            <geom class="right/collision" mesh="right/link_3_collision.004"/>
            <body name="right/link_4" pos="0.245 0 0.06">
              <inertial pos="0.0579784 0.00027145 0.0588445" quat="0.948688 0.0346237 0.307828 0.0635164"
                mass="0.457899" diaginertia="0.000670827 0.000661455 0.000288648"/>
              <joint name="right/joint_3" pos="0 0 0" axis="0 -1 0" range="-1.5708 1.5708" actuatorfrcrange="-7 7"
                armature="0.131812" damping="2.31571" frictionloss="0.004603"/>
              <geom class="right/visual" material="right/trossen_material" mesh="right/link_4"/>
              <geom class="right/collision" mesh="right/link_4_collision"/>
              <geom class="right/collision" mesh="right/link_4_collision.001"/>
              <geom class="right/collision" mesh="right/link_4_collision.002"/>
              <body name="right/link_5" pos="0.06775 0 0.0455">
                <inertial pos="0.00412447 -1.138e-05 -0.0428318" quat="0.496144 0.502128 0.503595 0.498098"
                  mass="0.366939" diaginertia="0.000320622 0.00026751 0.000189108"/>
                <joint name="right/joint_4" pos="0 0 0" axis="0 0 -1" range="-1.5708 1.5708" actuatorfrcrange="-7 7"
                  armature="0.138205" damping="2.36817"/>
                <geom class="right/visual" material="right/trossen_material" mesh="right/link_5"/>
                <geom class="right/collision" mesh="right/link_5_collision"/>
                <body name="right/link_6" pos="0.02895 0 -0.0455">
                  <inertial pos="0.0457277 -7.26e-06 1.402e-05" quat="0.500491 0.4997 -0.500266 0.499542"
                    mass="0.554693" diaginertia="0.001086 0.000824291 0.000487589"/>
                  <joint name="right/joint_5" pos="0 0 0" axis="1 0 0" range="-3.14159 3.14159" actuatorfrcrange="-7 7"
                    armature="0.039831" damping="0.684856"/>
                  <geom class="right/visual" material="right/trossen_material" mesh="right/link_6"/>
                  <geom class="right/collision" mesh="right/link_6_collision"/>
                  <site name="right/ee_gripper_link" pos="0.156062 0 0" size="0.01" group="5" rgba="1 0 0 1"/>
                  <body name="right/camera_mount_d405" pos="0.012 0 0">
                    <inertial pos="0.0302338 0.00679835 0.0500669" quat="0.501514 0.851949 0.0948108 -0.116954"
                      mass="0.0451801" diaginertia="3.52003e-05 2.55005e-05 1.80592e-05"/>
                    <geom class="right/visual" material="right/trossen_material" mesh="right/camera_mount_d405"/>
                    <geom class="right/collision" mesh="right/camera_mount_d405_collision"/>
                    <geom class="right/collision" mesh="right/camera_mount_d405_collision.001"/>
                    <body name="right/camera_link" pos="0.04665 0.009 0.054272" quat="0.984808 0 0.173648 0">
                      <inertial pos="0 0 0" mass="0.072" diaginertia="2.117e-05 1.3758e-05 1.3758e-05"/>
                      <geom class="right/visual" pos="0.0038 -0.009 0" quat="0.5 0.5 0.5 0.5"
                        material="right/trossen_material" mesh="right/d405"/>
                      <geom class="right/collision" size="0.0115 0.021 0.021" pos="-0.0078 -0.009 0" type="box"/>
                      <camera name="right/wrist_cam" pos="0 0 0" quat="0.5 0.5 -0.5 -0.5" resolution="1280 720"
                        sensorsize="0.003896 0.00214" focal="0.00193 0.00193"/>
                    </body>
                  </body>
                  <body name="right/carriage_right" pos="0.0865 -0.023 0">
                    <inertial pos="-0.00889602 0.00403514 0.00457901" quat="0.616415 0.778591 0.0236991 -0.115186"
                      mass="0.0503631" diaginertia="1.77614e-05 1.40157e-05 5.27289e-06"/>
                    <joint name="right/right_carriage_joint" pos="0 0 0" axis="0 -1 0" type="slide" range="-0.01 0.045"
                      actuatorfrcrange="-400 400" armature="2.57487" damping="2.37396" frictionloss="0.1"/>
                    <geom class="right/visual" material="right/trossen_material" mesh="right/carriage_right"/>
                    <geom class="right/collision" mesh="right/carriage_right_collision"/>
                    <body name="right/gripper_right">
                      <inertial pos="0.0189399 0.00901216 -0.00215461" quat="0.382396 0.419236 0.596564 0.567562"
                        mass="0.0309079" diaginertia="1.60975e-05 1.18601e-05 6.44247e-06"/>
                      <geom class="right/visual" material="right/trossen_material" mesh="right/gripper_right"/>
                      <geom class="right/gripper_collision" pos="0 -0.00154 0" quat="1 0 0 0"
                        mesh="right/gripper_right_collision"/>
                      <geom class="right/gripper_collision" size="0.005 0.016 0.028" pos="-0.004 0 0" type="box"/>
                      <geom name="right/gripper_right_pad" class="right/gripper_collision" size="0.008 0.002 0.005"
                        pos="0.0615 0.021 0" type="box" rgba="0 0.5 0 0.5"/>
                      <geom class="right/gripper_collision" size="0.001" pos="0.062 0.0223 -0.005" type="sphere"/>
                      <geom class="right/gripper_collision" size="0.001" pos="0.067 0.0223 0" type="sphere"/>
                      <geom class="right/gripper_collision" size="0.001" pos="0.062 0.0223 0.005" type="sphere"/>
                    </body>
                  </body>
                  <body name="right/carriage_left" pos="0.0865 0.023 0">
                    <inertial pos="-0.00889602 -0.00403515 -0.00457908" quat="0.616415 0.778591 0.0236991 -0.115186"
                      mass="0.0503631" diaginertia="1.77614e-05 1.40157e-05 5.27289e-06"/>
                    <joint name="right/left_carriage_joint" pos="0 0 0" axis="0 1 0" type="slide" range="-0.01 0.045"
                      actuatorfrcrange="-400 400" armature="0.0005" damping="10.7" frictionloss="0.018"/>
                    <geom class="right/visual" material="right/trossen_material" mesh="right/carriage_left"/>
                    <geom class="right/collision" mesh="right/carriage_left_collision"/>
                    <body name="right/gripper_left">
                      <inertial pos="0.0189399 -0.00901223 -0.00215453" quat="0.567562 0.596564 0.419236 0.382396"
                        mass="0.0309079" diaginertia="1.60975e-05 1.18601e-05 6.44247e-06"/>
                      <geom class="right/visual" material="right/trossen_material" mesh="right/gripper_left"/>
                      <geom class="right/gripper_collision" pos="0 0.00154 0" quat="1 0 0 0"
                        mesh="right/gripper_left_collision"/>
                      <geom class="right/gripper_collision" size="0.005 0.016 0.028" pos="-0.004 0 0" type="box"/>
                      <geom name="right/gripper_left_pad" class="right/gripper_collision" size="0.008 0.002 0.005"
                        pos="0.0615 -0.021 0" type="box" rgba="0 0.5 0 0.5"/>
                      <geom class="right/gripper_collision" size="0.001" pos="0.062 -0.0223 -0.005" type="sphere"/>
                      <geom class="right/gripper_collision" size="0.001" pos="0.067 -0.0223 0" type="sphere"/>
                      <geom class="right/gripper_collision" size="0.001" pos="0.062 -0.0223 0.005" type="sphere"/>
                    </body>
                  </body>
                </body>
              </body>
            </body>
          </body>
        </body>
      </body>
    </body>
  </worldbody>

  <contact>
    <exclude name="left_base_link_link_1" body1="left/base_link" body2="left/link_1"/>
    <exclude name="left_link_3_link_5" body1="left/link_3" body2="left/link_5"/>
    <exclude name="right_base_link_link_1" body1="right/base_link" body2="right/link_1"/>
    <exclude name="right_link_3_link_5" body1="right/link_3" body2="right/link_5"/>
  </contact>

  <actuator>
    <general name="left/joint_0" joint="left/joint_0" ctrlrange="-3.05433 3.05433" forcerange="-35 35" biastype="affine"
      gainprm="65.0922" biasprm="0 -65.0922"/>
    <general name="left/joint_1" joint="left/joint_1" ctrlrange="0 3.14159" forcerange="-144 144" biastype="affine"
      gainprm="83.6987" biasprm="0 -83.6987"/>
    <general name="left/joint_2" joint="left/joint_2" ctrlrange="0 2.35619" forcerange="-59 59" biastype="affine"
      gainprm="115.808" biasprm="0 -115.808"/>
    <general name="left/joint_3" joint="left/joint_3" ctrlrange="-1.5708 1.5708" forcerange="-22 22" biastype="affine"
      gainprm="45.9726" biasprm="0 -45.9726"/>
    <general name="left/joint_4" joint="left/joint_4" ctrlrange="-1.5708 1.5708" forcerange="-35 35" biastype="affine"
      gainprm="11.3646" biasprm="0 -11.3646"/>
    <general name="left/joint_5" joint="left/joint_5" ctrlrange="-3.14159 3.14159" forcerange="-35 35" biastype="affine"
      gainprm="4.38885" biasprm="0 -4.38885"/>
    <general name="left/right_carriage_joint" joint="left/right_carriage_joint" ctrlrange="-0.002 0.045"
      forcerange="-35 35" biastype="affine" gainprm="339.018" biasprm="0 -339.018"/>
    <general name="right/joint_0" joint="right/joint_0" ctrlrange="-3.05433 3.05433" forcerange="-35 35"
      biastype="affine" gainprm="65.0922" biasprm="0 -65.0922"/>
    <general name="right/joint_1" joint="right/joint_1" ctrlrange="0 3.14159" forcerange="-144 144" biastype="affine"
      gainprm="83.6987" biasprm="0 -83.6987"/>
    <general name="right/joint_2" joint="right/joint_2" ctrlrange="0 2.35619" forcerange="-59 59" biastype="affine"
      gainprm="115.808" biasprm="0 -115.808"/>
    <general name="right/joint_3" joint="right/joint_3" ctrlrange="-1.5708 1.5708" forcerange="-22 22" biastype="affine"
      gainprm="45.9726" biasprm="0 -45.9726"/>
    <general name="right/joint_4" joint="right/joint_4" ctrlrange="-1.5708 1.5708" forcerange="-35 35" biastype="affine"
      gainprm="11.3646" biasprm="0 -11.3646"/>
    <general name="right/joint_5" joint="right/joint_5" ctrlrange="-3.14159 3.14159" forcerange="-35 35"
      biastype="affine" gainprm="4.38885" biasprm="0 -4.38885"/>
    <general name="right/right_carriage_joint" joint="right/right_carriage_joint" ctrlrange="-0.002 0.045"
      forcerange="-35 35" biastype="affine" gainprm="339.018" biasprm="0 -339.018"/>
  </actuator>

  <keyframe>
    <key name="left/" time="199.554"
      qpos="0 -0.00231776 1.10539 0.652472 -0.000250995 0.000167313 0.02178 0.0217803 0 0 0 0 0 0 0 0"
      ctrl="0 0 1.10741 0.644028 0 0 0.02178 0 0 0 0 0 0 0"/>
    <key name="right/" time="199.554"
      qpos="0 0 0 0 0 0 0 0 0 -0.00231776 1.10539 0.652472 -0.000250995 0.000167313 0.02178 0.0217803"
      ctrl="0 0 0 0 0 0 0 0 0 1.10741 0.644028 0 0 0.02178"/>
  </keyframe>

  <equality>
    <joint joint1="left/left_carriage_joint" joint2="left/right_carriage_joint" polycoef="0 1 0 0 0"/>
    <joint joint1="right/left_carriage_joint" joint2="right/right_carriage_joint" polycoef="0 1 0 0 0"/>
  </equality>
</mujoco>
